<?xml version="1.0"?>
<robot xmlns:xacro="http://www.ros.org/wiki/xacro" name="inventory_bot">

  <xacro:property name="chassis_length" value="0.4"/>
  <xacro:property name="chassis_width" value="0.25"/>
  <xacro:property name="chassis_height" value="0.1"/>
  <xacro:property name="chassis_mass" value="5.0"/>
  
  <xacro:property name="wheel_radius" value="0.1"/>
  <xacro:property name="wheel_length" value="0.05"/>
  <xacro:property name="wheel_mass" value="0.5"/>
  <xacro:property name="wheel_x_offset" value="0.1"/> 
  
  <xacro:property name="caster_radius" value="0.05"/>
  <xacro:property name="caster_mass" value="0.1"/>

  <material name="blue"><color rgba="0.1 0.1 0.8 1.0"/></material>
  <material name="black"><color rgba="0.2 0.2 0.2 1.0"/></material>
  <material name="red"><color rgba="0.8 0.1 0.1 1.0"/></material>
  <material name="dark_grey"><color rgba="0.2 0.2 0.2 1.0"/></material>

  <link name="base_footprint"/>
  
  <link name="base_link">
    <visual>
      <geometry><box size="${chassis_length} ${chassis_width} ${chassis_height}"/></geometry>
      <material name="blue"/>
    </visual>
    <collision>
      <geometry><box size="${chassis_length} ${chassis_width} ${chassis_height}"/></geometry>
    </collision>
    <inertial>
      <mass value="${chassis_mass}"/>
      <inertia 
        ixx="${(1.0/12.0)*chassis_mass*(chassis_width*chassis_width+chassis_height*chassis_height)}" ixy="0.0" ixz="0.0" 
        iyy="${(1.0/12.0)*chassis_mass*(chassis_length*chassis_length+chassis_height*chassis_height)}" iyz="0.0" 
        izz="${(1.0/12.0)*chassis_mass*(chassis_length*chassis_length+chassis_width*chassis_width)}"/>
    </inertial>
  </link>

  <joint name="base_joint" type="fixed">
    <parent link="base_footprint"/>
    <child link="base_link"/>
    <origin xyz="0.0 0.0 ${wheel_radius}" rpy="0.0 0.0 0.0"/>
  </joint>

  <xacro:macro name="generate_wheel" params="side reflect">
    <link name="${side}_wheel">
      <visual>
        <origin xyz="0 0 0" rpy="${pi/2} 0 0"/>
        <geometry><cylinder radius="${wheel_radius}" length="${wheel_length}"/></geometry>
        <material name="black"/>
      </visual>
      <collision>
        <origin xyz="0 0 0" rpy="${pi/2} 0 0"/>
        <geometry><cylinder radius="${wheel_radius}" length="${wheel_length}"/></geometry>
      </collision>
      <inertial>
        <mass value="${wheel_mass}"/>
        <inertia 
          ixx="${(1.0/12.0)*wheel_mass*(3.0*wheel_radius*wheel_radius+wheel_length*wheel_length)}" ixy="0.0" ixz="0.0" 
          iyy="${0.5*wheel_mass*wheel_radius*wheel_radius}" iyz="0.0" 
          izz="${(1.0/12.0)*wheel_mass*(3.0*wheel_radius*wheel_radius+wheel_length*wheel_length)}"/>
      </inertial>
    </link>
    <joint name="${side}_wheel_joint" type="continuous">
      <parent link="base_link"/>
      <child link="${side}_wheel"/>
      <origin xyz="${wheel_x_offset} ${reflect*(chassis_width/2 + wheel_length/2)} 0.0" rpy="0 0 0"/>
      <axis xyz="0 1 0"/>
    </joint>
  </xacro:macro>

  <xacro:generate_wheel side="left" reflect="1"/>
  <xacro:generate_wheel side="right" reflect="-1"/>

  <link name="caster_wheel">
    <visual>
      <geometry><sphere radius="${caster_radius}"/></geometry>
      <material name="dark_grey"/>
    </visual>
    <collision>
      <geometry><sphere radius="${caster_radius}"/></geometry>
    </collision>
    <inertial>
      <mass value="${caster_mass}"/>
      <inertia 
        ixx="${(2.0/5.0)*caster_mass*caster_radius*caster_radius}" ixy="0.0" ixz="0.0" 
        iyy="${(2.0/5.0)*caster_mass*caster_radius*caster_radius}" iyz="0.0" 
        izz="${(2.0/5.0)*caster_mass*caster_radius*caster_radius}"/>
    </inertial>
  </link>
  <joint name="caster_wheel_joint" type="fixed">
    <parent link="base_link"/>
    <child link="caster_wheel"/>
    <origin xyz="${-chassis_length/2 + caster_radius} 0.0 ${-(wheel_radius - caster_radius)}" rpy="0 0 0"/>
  </joint>

  <gazebo reference="caster_wheel">
    <mu1>0.001</mu1>
    <mu2>0.001</mu2>
    <material>Gazebo/DarkGrey</material>
  </gazebo>

  <link name="lidar_link">
    <visual><geometry><cylinder radius="0.05" length="0.05"/></geometry><material name="red"/></visual>
    <collision><geometry><cylinder radius="0.05" length="0.05"/></geometry></collision>
    <inertial><mass value="0.1"/><inertia ixx="0.0001" ixy="0" ixz="0" iyy="0.0001" iyz="0" izz="0.0001"/></inertial>
  </link>
  <joint name="lidar_joint" type="fixed">
    <parent link="base_link"/>
    <child link="lidar_link"/>
    <origin xyz="0 0 0.075" rpy="0 0 0"/>
  </joint>

  <link name="camera_link">
    <visual><geometry><box size="0.02 0.05 0.05"/></geometry><material name="red"/></visual>
    <collision><geometry><box size="0.02 0.05 0.05"/></geometry></collision>
    <inertial><mass value="0.1"/><inertia ixx="0.0001" ixy="0" ixz="0" iyy="0.0001" iyz="0" izz="0.0001"/></inertial>
  </link>
  <joint name="camera_joint" type="fixed">
    <parent link="base_link"/>
    <child link="camera_link"/>
    <origin xyz="0.21 0 0.0" rpy="0 0 0"/> 
  </joint>
  
  <link name="camera_link_optical"/>
  <joint name="camera_optical_joint" type="fixed">
    <parent link="camera_link"/>
    <child link="camera_link_optical"/>
    <origin xyz="0 0 0" rpy="${-pi/2} 0 ${-pi/2}"/>
  </joint>

  <gazebo>
    <plugin filename="gz-sim-diff-drive-system" name="gz::sim::systems::DiffDrive">
      <left_joint>left_wheel_joint</left_joint>
      <right_joint>right_wheel_joint</right_joint>
      <wheel_separation>${chassis_width + wheel_length}</wheel_separation>
      <wheel_radius>${wheel_radius}</wheel_radius>
      <odom_publish_frequency>50</odom_publish_frequency>
      <topic>/cmd_vel</topic>
      <odom_topic>/odom</odom_topic>
      <tf_topic>/tf</tf_topic>
      <frame_id>odom</frame_id>
      <child_frame_id>base_footprint</child_frame_id>
    </plugin>
    <plugin filename="gz-sim-joint-state-publisher-system" name="gz::sim::systems::JointStatePublisher">
      <topic>/joint_states</topic>
    </plugin>
  </gazebo>

  <gazebo reference="lidar_link">
    <sensor name="lidar" type="gpu_lidar">
      <topic>/scan</topic>
      <gz_frame_id>lidar_link</gz_frame_id>
      <update_rate>10</update_rate>
      <ray>
        <scan>
          <horizontal>
            <samples>360</samples>
            <resolution>1</resolution>
            <min_angle>-3.14159</min_angle>
            <max_angle>3.14159</max_angle>
          </horizontal>
        </scan>
        <range><min>0.3</min><max>12.0</max></range>
      </ray>
      <always_on>true</always_on>
      <visualize>true</visualize>
    </sensor>
  </gazebo>

  <gazebo reference="camera_link">
    <sensor name="camera" type="camera">
      <topic>/camera/image_raw</topic>
      <gz_frame_id>camera_link_optical</gz_frame_id>
      <camera>
        <horizontal_fov>1.047</horizontal_fov>
        <image><width>640</width><height>480</height></image>
        <clip><near>0.1</near><far>100</far></clip>
      </camera>
      <always_on>true</always_on>
      <update_rate>30</update_rate>
      <visualize>true</visualize>
    </sensor>
  </gazebo>

</robot>
